Workbook

Sheet Hoja1
A2: FARMACIA UNIVERSIDAD
A3: C A P P O - U C L A
A4: Carrera 21 entre Calles 12 y 13 Nro 12-13 telef. 0251-2524973/2527081
A5: Relación de Cobranza
A6: CAPPO - UCLA
A7: Desde 22/10/12 Hasta: 31/10/12
A8: Fecha | B8: Apellido y Nombre | C8: Cédula | D8: Cod. Socio | E8: Factura | F8: Monto | G8: Dcto. Clte. | H8: Total Facturas | J8: Dcto. Cap. | K8: IVA | L8: Neto
A9: 41204 | B9: ALVARADO RAMIRO | C9: 4385047 | D9: 00117 | E9: 519223 | F9: 712 | G9: 142.4 | H9: 569.6 | J9: 28.48 | K9: 0 | L9: 541.12
A10: 41204 | B10: ALVARADO RAMON | C10: 10784623 | D10: 00114 | E10: 519339 | F10: 303.18 | G10: 59.57 | H10: 244.25 | J10: 12.2125 | K10: 0.64 | L10: 232.0375
A11: 41204 | B11: ALVAREZ NINOSKA | C11: 18785684 | D11: 02613 | E11: 519180 | F11: 558.36 | G11: 72 | H11: 498.36 | J11: 24.918 | K11: 12 | L11: 473.442
A12: 41204 | B12: ALVAREZ THAIS | C12: 13346269 | D12: 00192 | E12: 519316 | F12: 200.54 | G12: 22.4 | H12: 187.66 | J12: 9.383 | K12: 9.52 | L12: 178.277
A13: 41204 | B13: ANDRADE FREDDY | C13: 13180551 | D13: 00183 | E13: 519056 | F13: 458 | G13: 91.6 | H13: 366.4 | I13: 392.54 | J13: 18.32 | K13: 0 | L13: 348.08
A14: 41204 | B14: ANDRADE FREDDY | C14: 13180551 | D14: 00183 | E14: 519057 | F14: 26.14 | G14: 0 | H14: 26.14 | J14: 0 | K14: 0 | L14: 26.14
A15: 41205 | B15: ANZOLA BLADIMIR | C15: 11269196 | D15: 00149 | E15: 519153 | F15: 258.29 | G15: 50.85 | H15: 207.44 | I15: 348.24 | J15: 10.372 | K15: 0 | L15: 197.068
A16: 41205 | B16: ANZOLA BLADIMIR | C16: 11269196 | D16: 00149 | E16: 519198 | F16: 176 | G16: 35.2 | H16: 140.8 | J16: 7.04 | K16: 0 | L16: 133.76
A17: 41205 | B17: ARRIECHE P. SILVIO | C17: 12848719 | D17: 00174 | E17: 519107 | F17: 126 | G17: 25.2 | H17: 100.8 | J17: 5.04 | K17: 0 | L17: 95.76
A18: 41205 | B18: ARRIECHE RAFAEL | C18: 7444842 | D18: 00186 | E18: 519118 | F18: 347.1 | G18: 67.4 | H18: 279.7 | J18: 13.985 | K18: 0 | L18: 265.715
A19: 41205 | B19: BELLO LAYA JULIO | C19: 7344290 | D19: 0222 | E19: 519165 | F19: 206 | G19: 41.2 | H19: 164.8 | J19: 8.24 | K19: 0 | L19: 156.56
A20: 41205 | B20: CARRASCO TONDIS | C20: 16770549 | D20: 00387 | E20: 519054 | F20: 462 | G20: 92.4 | H20: 369.6 | J20: 18.48 | K20: 0 | L20: 351.12
A21: 41205 | B21: CASTILLO JOSE | C21: 3084978 | D21: 00314 | E21: 519257 | F21: 241.88 | G21: 40.9 | H21: 200.98 | I21: 272.98 | J21: 10.049 | K21: 0 | L21: 190.931
A22: 41205 | B22: CASTILLO JOSE | C22: 3084978 | D22: 00314 | E22: 519258 | F22: 90 | G22: 18 | H22: 72 | J22: 3.6 | K22: 0 | L22: 68.4
A23: 41205 | B23: CASTILLO HONORIO | C23: 9540845 | D23: 00355 | E23: 519082 | F23: 87.78 | G23: 13.6 | H23: 74.18 | J23: 3.709 | K23: 0 | L23: 70.471
A24: 41205 | B24: CASTILLO M. RAMON | C24: 5239261 | D24: 00340 | E24: 519276 | F24: 436 | G24: 87.2 | H24: 348.8 | J24: 17.44 | K24: 0 | L24: 331.36
A25: 41205 | B25: COLMENAREZ MIGUEL | C25: 7310425 | D25: 00346 | E25: 519156 | F25: 712 | G25: 142.4 | H25: 569.6 | J25: 28.48 | K25: 0 | L25: 541.12
A26: 41205 | B26: COLMENAREZ LUIS | C26: 7350162 | D26: 00363 | E26: 519281 | F26: 123.08 | G26: 0 | H26: 136.58 | J26: 0 | K26: 13.5 | L26: 136.58
A27: 41205 | B27: CONDES HECTOR | C27: 12018852 | D27: 00381 | E27: 519076 | F27: 213 | G27: 42.6 | H27: 170.4 | I27: 282.4 | J27: 8.52 | K27: 0 | L27: 161.88
A28: 41205 | B28: CONDES HECTOR | C28: 12018852 | D28: 00381 | E28: 519077 | F28: 140 | G28: 28 | H28: 112 | J28: 5.6 | K28: 0 | L28: 106.4
A29: 41205 | B29: DAVILA CHACON INGRID | C29: 9211039 | D29: 00522 | E29: 519073 | F29: 700 | G29: 140 | H29: 560 | J29: 28 | K29: 0 | L29: 532
A30: 41205 | B30: DIAZ DIAZ JUAN | C30: 3039370 | D30: 00505 | E30: 519151 | F30: 712 | G30: 142.4 | H30: 569.6 | J30: 28.48 | K30: 0 | L30: 541.12
A31: 41205 | B31: ESCALONA MOISES | C31: 11586448 | D31: 00629 | E31: 519105 | F31: 423.68 | G31: 84.74 | H31: 338.94 | I31: 342.97 | J31: 16.947 | K31: 0 | L31: 321.993
A32: 41206 | B32: ESCALONA MOISES | C32: 11586448 | D32: 00629 | E32: 519106 | F32: 3.6 | G32: 0 | H32: 4.03 | J32: 0 | K32: 0.43 | L32: 4.03
A33: 41206 | B33: GARCES NELLY | C33: 4732618 | D33: 00800 | E33: 519113 | F33: 492 | G33: 98.4 | H33: 393.6 | I33: 451.2 | J33: 19.68 | K33: 0 | L33: 373.92
A34: 41206 | B34: GARCES NELLY | C34: 4732618 | D34: 00800 | E34: 519114 | F34: 72 | G34: 14.4 | H34: 57.6 | J34: 2.88 | K34: 0 | L34: 54.72
A35: 41206 | B35: GIL PABLO | C35: 3857667 | D35: 00814 | E35: 519023 | F35: 220 | G35: 24.2 | H35: 195.8 | I35: 765.4 | J35: 9.79 | K35: 0 | L35: 186.01
A36: 41206 | B36: GIL PABLO | C36: 3857667 | D36: 00814 | E36: 519256 | F36: 712 | G36: 142.4 | H36: 569.6 | J36: 28.48 | K36: 0 | L36: 541.12
A37: 41206 | B37: GIL RAFAEL | C37: 9604593 | D37: 00925 | E37: 519262 | F37: 200.18 | G37: 30.2 | H37: 169.98 | J37: 8.499 | K37: 0 | L37: 161.481
A38: 41206 | B38: GIMENEZ ERNESTO | C38: 7436996 | D38: 00919 | E38: 519100 | F38: 481 | G38: 96.2 | H38: 384.8 | J38: 19.24 | K38: 0 | L38: 365.56
A39: 41206 | B39: GIMENEZ JOSE | C39: 12851330 | D39: 00882 | E39: 518997 | F39: 198.35 | G39: 36 | H39: 162.35 | J39: 8.1175 | K39: 0 | L39: 154.2325
A40: 41206 | B40: GOMEZ MEDINA JUAN | C40: 12704927 | D40: 00918 | E40: 519084 | F40: 82 | G40: 16.4 | H40: 65.6 | J40: 3.28 | K40: 0 | L40: 62.32
A41: 41206 | B41: GONZALEZ ALBERTO | C41: 9639201 | D41: 00862 | E41: 519390 | F41: 263.5 | G41: 51.64 | H41: 211.86 | J41: 10.593 | K41: 0 | L41: 201.267
...

Sheet Hoja2
A1: =CONCATENATE("V",Hoja1!C9) -> V4385047 | B1: =+Hoja1!B9 -> ALVARADO RAMIRO | C1: =+Hoja1!H9 -> 569.6 | D1: =+Hoja1!J9 -> 28.48 | E1: =+Hoja1!L9 -> 541.12
A2: =CONCATENATE("V",Hoja1!C10) -> V10784623 | B2: =+Hoja1!B10 -> ALVARADO RAMON | C2: =+Hoja1!H10 -> 244.25 | D2: =+Hoja1!J10 -> 12.2125 | E2: =+Hoja1!L10 -> 232.0375
A3: =CONCATENATE("V",Hoja1!C11) -> V18785684 | B3: =+Hoja1!B11 -> ALVAREZ NINOSKA | C3: =+Hoja1!H11 -> 498.36 | D3: =+Hoja1!J11 -> 24.918 | E3: =+Hoja1!L11 -> 473.442
A4: =CONCATENATE("V",Hoja1!C12) -> V13346269 | B4: =+Hoja1!B12 -> ALVAREZ THAIS | C4: =+Hoja1!H12 -> 187.66 | D4: =+Hoja1!J12 -> 9.383 | E4: =+Hoja1!L12 -> 178.277
A5: =CONCATENATE("V",Hoja1!C13) -> V13180551 | B5: =+Hoja1!B13 -> ANDRADE FREDDY | C5: =+Hoja1!H13 -> 366.4 | D5: =+Hoja1!J13 -> 18.32 | E5: =+Hoja1!L13 -> 348.08
A6: =CONCATENATE("V",Hoja1!C14) -> V13180551 | B6: =+Hoja1!B14 -> ANDRADE FREDDY | C6: =+Hoja1!H14 -> 26.14 | D6: =+Hoja1!J14 -> 0 | E6: =+Hoja1!L14 -> 26.14
A7: =CONCATENATE("V",Hoja1!C15) -> V11269196 | B7: =+Hoja1!B15 -> ANZOLA BLADIMIR | C7: =+Hoja1!H15 -> 207.44 | D7: =+Hoja1!J15 -> 10.372 | E7: =+Hoja1!L15 -> 197.068
A8: =CONCATENATE("V",Hoja1!C16) -> V11269196 | B8: =+Hoja1!B16 -> ANZOLA BLADIMIR | C8: =+Hoja1!H16 -> 140.8 | D8: =+Hoja1!J16 -> 7.04 | E8: =+Hoja1!L16 -> 133.76
A9: =CONCATENATE("V",Hoja1!C17) -> V12848719 | B9: =+Hoja1!B17 -> ARRIECHE P. SILVIO | C9: =+Hoja1!H17 -> 100.8 | D9: =+Hoja1!J17 -> 5.04 | E9: =+Hoja1!L17 -> 95.76
A10: =CONCATENATE("V",Hoja1!C18) -> V7444842 | B10: =+Hoja1!B18 -> ARRIECHE RAFAEL | C10: =+Hoja1!H18 -> 279.7 | D10: =+Hoja1!J18 -> 13.985 | E10: =+Hoja1!L18 -> 265.715
A11: =CONCATENATE("V",Hoja1!C19) -> V7344290 | B11: =+Hoja1!B19 -> BELLO LAYA JULIO | C11: =+Hoja1!H19 -> 164.8 | D11: =+Hoja1!J19 -> 8.24 | E11: =+Hoja1!L19 -> 156.56
A12: =CONCATENATE("V",Hoja1!C20) -> V16770549 | B12: =+Hoja1!B20 -> CARRASCO TONDIS | C12: =+Hoja1!H20 -> 369.6 | D12: =+Hoja1!J20 -> 18.48 | E12: =+Hoja1!L20 -> 351.12
... A83: =CONCATENATE("V",Hoja1!C91) -> V7449457 | B83: =+Hoja1!B91 -> VISCAYA PEDRO | C83: =+Hoja1!H91 -> 174.4 | D83: =+Hoja1!J91 -> 8.72 | E83: =+Hoja1!L91 -> 165.68

Sheet Hoja3
