Workbook

Sheet CAPPOUCLA
A2: FARMACIA UNIVERSIDAD
A3: C A P P O - U C L A
A4: Carrera 21 entre Calles 12 y 13 Nro 12-13 telef. 0251-2524973/2527081
A5: Relación de Cobranza
A6: CAPPO - UCLA
A7: Desde 01/11/12 Hasta: 10/11/12
A8: Fecha | B8: Apellido y Nombre | C8: Cédula | D8: Cod. Socio | E8: Factura | F8: Monto | G8: Dcto. Clte. | H8: Total Facturas | J8: Dcto. Cap. | K8: IVA | L8: Neto
A9: 41214 | B9: ALVARADO PEDRO | C9: 2186056 | D9: 00140 | E9: 519774 | F9: 70 | G9: 14 | H9: 56 | J9: =H9*5% -> 2.8 | K9: 0 | L9: 53.2
A10: 41214 | B10: ALVARADO YULITH | C10: 7419740 | D10: 00138 | E10: 519418 | F10: 404.65 | G10: 79.75 | H10: 324.9 | I10: 2396.56 | J10: =H10*5% -> 16.245 | K10: 0 | L10: 308.655
A11: 41214 | B11: ALVARADO YULITH | C11: 7419740 | D11: 00138 | E11: 519760 | F11: 1168.09 | G11: 233.61 | H11: 934.48 | J11: =H11*5% -> 46.724 | K11: 0 | L11: 887.756
A12: 41214 | B12: ALVARADO YULITH | C12: 7419740 | D12: 00138 | E12: 519761 | F12: 1220.77 | G12: 235.39 | H12: 985.38 | J12: =H12*5% -> 49.269 | K12: 0 | L12: 936.111
A13: 41214 | B13: ALVARADO YULITH | C13: 7419740 | D13: 00138 | E13: 519762 | F13: 135.54 | G13: 0 | H13: 151.8 | J13: =H13*5% -> 7.59 | K13: 16.26 | L13: 151.8
A14: 41214 | B14: ALVAREZ JOSE | C14: 12020535 | D14: 00160 | E14: 519520 | F14: 377.56 | G14: 68.06 | H14: 309.5 | I14: 461.7 | J14: =H14*5% -> 15.475 | K14: 0 | L14: 294.025
A15: 41214 | B15: ALVAREZ JOSE | C15: 12020535 | D15: 00160 | E15: 519521 | F15: 187.9 | G15: 35.7 | H15: 152.2 | J15: =H15*5% -> 7.61 | K15: 0 | L15: 144.59
A16: 41214 | B16: AMARO PABLO | C16: 12701301 | D16: 00187 | E16: 519732 | F16: 377.39 | G16: 75.48 | H16: 301.91 | J16: =H16*5% -> 15.0955 | K16: 0 | L16: 286.8145
A17: 41214 | B17: CASTAÑEDA FRANCISCO | C17: 7442445 | D17: 00352 | E17: 519713 | F17: 215.69 | G17: 41.8 | H17: 173.89 | I17: 424.22 | J17: =H17*5% -> 8.6945 | K17: 0 | L17: 165.1955
A18: 41214 | B18: CASTAÑEDA FRANCISCO | C18: 7442445 | D18: 00352 | E18: 519714 | F18: 250.73 | G18: 38 | H18: 220.01 | J18: =H18*5% -> 11.0005 | K18: 7.28 | L18: 209.0095
A19: 41214 | B19: CASTAÑEDA FRANCISCO | C19: 7442445 | D19: 00352 | E19: 519715 | F19: 29 | G19: 0 | H19: 30.32 | J19: =H19*5% -> 1.516 | K19: 1.32 | L19: 30.32
A20: 41214 | B20: CASTELLANOS VICENTE | C20: 12314254 | D20: 00304 | E20: 519424 | F20: 379 | G20: 75.8 | H20: 303.2 | J20: =H20*5% -> 15.16 | K20: 0 | L20: 288.04
A21: 41214 | B21: CASTILLO JOSE | C21: 10846532 | D21: 00361 | E21: 519658 | F21: 740 | G21: 148 | H21: 592 | J21: =H21*5% -> 29.6 | K21: 0 | L21: 562.4
A22: 41214 | B22: CHIRINOS GREGORIO | C22: 7446644 | D22: 00366 | E22: 519698 | F22: 588.25 | G22: 117 | H22: 471.25 | I22: 729.85 | J22: =H22*5% -> 23.5625 | K22: 0 | L22: 447.6875
A23: 41215 | B23: CHIRINOS GREGORIO | C23: 7446644 | D23: 00366 | E23: 519527 | F23: 314.75 | G23: 57.8 | H23: 258.6 | J23: =H23*5% -> 12.93 | K23: 1.65 | L23: 245.67
A24: 41215 | B24: CORRALES CLARISA | C24: 9609337 | D24: 00343 | E24: 519441 | F24: 143.44 | G24: 23 | H24: 120.44 | I24: 717.38 | J24: =H24*5% -> 6.022 | K24: 0 | L24: 114.418
A25: 41215 | B25: CORRALES CLARISA | C25: 9609337 | D25: 00343 | E25: 519554 | F25: 737.94 | G25: 141 | H25: 596.94 | J25: =H25*5% -> 29.847 | K25: 0 | L25: 567.093
A26: 41215 | B26: DUNO RIVERO EDGAR | C26: 9544345 | D26: 00511 | E26: 519770 | F26: 97.38 | G26: 0 | H26: 101.58 | J26: =H26*5% -> 5.079 | K26: 4.2 | L26: 101.58
A27: 41215 | B27: DURAN ADRIAN | C27: 4727740 | D27: 00500 | E27: 519676 | F27: 187.19 | G27: 0 | H27: 194.99 | J27: =H27*5% -> 9.7495 | K27: 7.8 | L27: 194.99
A28: 41215 | B28: DURAN JESUS | C28: 11594236 | D28: 00512 | E28: 519480 | F28: 633 | G28: 126.6 | H28: 506.4 | J28: =H28*5% -> 25.32 | K28: 0 | L28: 481.08
A29: 41215 | B29: FRANCO ALIBERT | C29: 12023306 | D29: 00721 | E29: 519420 | F29: 910 | G29: 182 | H29: 728 | J29: =H29*5% -> 36.4 | K29: 0 | L29: 691.6
A30: 41216 | B30: GALLARDO SILVERIO | C30: 3963688 | D30: 00863 | E30: 519621 | F30: 131 | G30: 26.2 | H30: 104.8 | I30: 543.53 | J30: =H30*5% -> 5.24 | K30: 0 | L30: 99.56
A31: 41216 | B31: GALLARDO SILVERIO | C31: 3963688 | D31: 00863 | E31: 519625 | F31: 548.41 | G31: 109.68 | H31: 438.73 | J31: =H31*5% -> 21.9365 | K31: 0 | L31: 416.7935
A32: 41216 | B32: GIL PABLO | C32: 3857667 | D32: 00814 | E32: 519651 | F32: 168 | G32: 33.6 | H32: 134.4 | J32: =H32*5% -> 6.72 | K32: 0 | L32: 127.68
A33: 41216 | B33: GOMEZ MEDINA JUAN | C33: 12704927 | D33: 00918 | E33: 519602 | F33: 311.55 | G33: 62.31 | H33: 249.24 | J33: =H33*5% -> 12.462 | K33: 0 | L33: 236.778
A34: 40913 | B34: GRATEROL JHONNY | C34: 10849907 | D34: 00938 | E34: 519427 | F34: 512.65 | G34: 102.53 | H34: 410.12 | J34: =H34*5% -> 20.506 | K34: 0 | L34: 389.614
A35: 40913 | B35: GRATEROL YAILILI | C35: 9615964 | D35: 00887 | E35: 519667 | F35: 1090.62 | G35: 207.84 | H35: 882.78 | I35: 1544.51 | J35: =H35*5% -> 44.139 | K35: 0 | L35: 838.641
A36: 40913 | B36: GRATEROL YAILILI | C36: 9615964 | D36: 00887 | E36: 519668 | F36: 396.19 | G36: 66.24 | H36: 337.75 | J36: =H36*5% -> 16.8875 | K36: 7.8 | L36: 320.8625
A37: 40913 | B37: GRATEROL YAILILI | C37: 9615964 | D37: 00887 | E37: 519669 | F37: 312.13 | G37: 46 | H37: 274.89 | J37: =H37*5% -> 13.7445 | K37: 8.76 | L37: 261.1455
A38: 40913 | B38: GRATEROL YAILILI | C38: 9615964 | D38: 00887 | E38: 519670 | F38: 49.09 | G38: 0 | H38: 49.09 | J38: =H38*5% -> 2.4545 | K38: 0 | L38: 49.09
A39: 41219 | B39: GUANIPA MIGUEL | C39: 7391472 | D39: 00896 | E39: 519754 | F39: 205.99 | G39: 26 | H39: 189.11 | J39: =H39*5% -> 9.4555 | K39: 9.12 | L39: 179.6545
A40: 41219 | B40: GUASIMUCARO HENRY | C40: 7426046 | D40: 00889 | E40: 519426 | F40: 270 | G40: 54 | H40: 216 | J40: =H40*5% -> 10.8 | K40: 0 | L40: 205.2
A41: 41219 | B41: GUERRA JOSE | C41: 7309375 | D41: 00879 | E41: 519816 | F41: 200 | G41: 40 | H41: 160 | I41: 240.11 | J41: =H41*5% -> 8 | K41: 0 | L41: 152
...

Sheet EMPLEADOS CAPPO
A4: C A P P O - U C L A
A5: Carrera 21 entre Calles 12 y 13 Nro 12-13 telef. 0251-2524973/2527081
A6: Relación de Cobranza
A7: EMPLEADOS CAPPO UCLA
A8: Desde 1/11/12 Hasta: 10/11/12
A9: Fecha | B9: Apellido y Nombre | C9: Cédula | D9: Cod. Socio | E9: Factura | F9: Monto | G9: Dcto. Clte. | H9: Total Facturas | J9: Dcto. Cap. | K9: IVA | L9: Neto
A10: 41222 | B10: RODRIGUEZ AIDA | C10: 9613403 | D10: 00403 | E10: 519769 | F10: 464.01 | G10: 75.95 | H10: 388.06 | J10: =H10*5% -> 19.403 | K10: 0 | L10: 368.657
F11: =SUM(F10) -> 464.01 | G11: =SUM(G10) -> 75.95 | H11: =SUM(H10) -> 388.06 | J11: =SUM(J10) -> 19.403 | K11: =SUM(K10) -> 0 | L11: =SUM(L10) -> 368.657
I15: =H11-J11 -> 368.657
B18: Elaborado Por: | E18: Recibido: (Firma y Sello)
B21: Yuris Reyes | E21: CAPPO-UCLA

Sheet Hoja3
A1: V | B1: =+CAPPOUCLA!C9 -> 2186056 | C1: =+CAPPOUCLA!B9 -> ALVARADO PEDRO | D1: =+CAPPOUCLA!H9 -> 56 | E1: =+CAPPOUCLA!J9 -> 2.8 | F1: =+CAPPOUCLA!L9 -> 53.2
A2: V | B2: =+CAPPOUCLA!C10 -> 7419740 | C2: =+CAPPOUCLA!B10 -> ALVARADO YULITH | D2: =+CAPPOUCLA!H10 -> 324.9 | E2: =+CAPPOUCLA!J10 -> 16.245 | F2: =+CAPPOUCLA!L10 -> 308.655
A3: V | B3: =+CAPPOUCLA!C11 -> 7419740 | C3: =+CAPPOUCLA!B11 -> ALVARADO YULITH | D3: =+CAPPOUCLA!H11 -> 934.48 | E3: =+CAPPOUCLA!J11 -> 46.724 | F3: =+CAPPOUCLA!L11 -> 887.756
A4: V | B4: =+CAPPOUCLA!C12 -> 7419740 | C4: =+CAPPOUCLA!B12 -> ALVARADO YULITH | D4: =+CAPPOUCLA!H12 -> 985.38 | E4: =+CAPPOUCLA!J12 -> 49.269 | F4: =+CAPPOUCLA!L12 -> 936.111
A5: V | B5: =+CAPPOUCLA!C13 -> 7419740 | C5: =+CAPPOUCLA!B13 -> ALVARADO YULITH | D5: =+CAPPOUCLA!H13 -> 151.8 | E5: =+CAPPOUCLA!J13 -> 7.59 | F5: =+CAPPOUCLA!L13 -> 151.8
A6: V | B6: =+CAPPOUCLA!C14 -> 12020535 | C6: =+CAPPOUCLA!B14 -> ALVAREZ JOSE | D6: =+CAPPOUCLA!H14 -> 309.5 | E6: =+CAPPOUCLA!J14 -> 15.475 | F6: =+CAPPOUCLA!L14 -> 294.025
A7: V | B7: =+CAPPOUCLA!C15 -> 12020535 | C7: =+CAPPOUCLA!B15 -> ALVAREZ JOSE | D7: =+CAPPOUCLA!H15 -> 152.2 | E7: =+CAPPOUCLA!J15 -> 7.61 | F7: =+CAPPOUCLA!L15 -> 144.59
A8: V | B8: =+CAPPOUCLA!C16 -> 12701301 | C8: =+CAPPOUCLA!B16 -> AMARO PABLO | D8: =+CAPPOUCLA!H16 -> 301.91 | E8: =+CAPPOUCLA!J16 -> 15.0955 | F8: =+CAPPOUCLA!L16 -> 286.8145
A9: V | B9: =+CAPPOUCLA!C17 -> 7442445 | C9: =+CAPPOUCLA!B17 -> CASTAÑEDA FRANCISCO | D9: =+CAPPOUCLA!H17 -> 173.89 | E9: =+CAPPOUCLA!J17 -> 8.6945 | F9: =+CAPPOUCLA!L17 -> 165.1955
A10: V | B10: =+CAPPOUCLA!C18 -> 7442445 | C10: =+CAPPOUCLA!B18 -> CASTAÑEDA FRANCISCO | D10: =+CAPPOUCLA!H18 -> 220.01 | E10: =+CAPPOUCLA!J18 -> 11.0005 | F10: =+CAPPOUCLA!L18 -> 209.0095
A11: V | B11: =+CAPPOUCLA!C19 -> 7442445 | C11: =+CAPPOUCLA!B19 -> CASTAÑEDA FRANCISCO | D11: =+CAPPOUCLA!H19 -> 30.32 | E11: =+CAPPOUCLA!J19 -> 1.516 | F11: =+CAPPOUCLA!L19 -> 30.32
A12: V | B12: =+CAPPOUCLA!C20 -> 12314254 | C12: =+CAPPOUCLA!B20 -> CASTELLANOS VICENTE | D12: =+CAPPOUCLA!H20 -> 303.2 | E12: =+CAPPOUCLA!J20 -> 15.16 | F12: =+CAPPOUCLA!L20 -> 288.04
... A79: V | B79: =+CAPPOUCLA!C87 -> 9613403 | C79: =+CAPPOUCLA!B87 -> RODRIGUEZ AIDA | D79: =+CAPPOUCLA!H87 -> 388.06 | E79: =+CAPPOUCLA!J87 -> 19.403 | F79: =+CAPPOUCLA!L87 -> 368.657

Sheet Hoja1
A1: =CONCATENATE(Hoja3!A1,Hoja3!B1) -> V2186056 | B1: =+Hoja3!C1 -> ALVARADO PEDRO | C1: =+Hoja3!D1 -> 56 | D1: =+Hoja3!E1 -> 2.8 | E1: =+Hoja3!F1 -> 53.2
A2: =CONCATENATE(Hoja3!A2,Hoja3!B2) -> V7419740 | B2: =+Hoja3!C2 -> ALVARADO YULITH | C2: =+Hoja3!D2 -> 324.9 | D2: =+Hoja3!E2 -> 16.245 | E2: =+Hoja3!F2 -> 308.655
A3: =CONCATENATE(Hoja3!A3,Hoja3!B3) -> V7419740 | B3: =+Hoja3!C3 -> ALVARADO YULITH | C3: =+Hoja3!D3 -> 934.48 | D3: =+Hoja3!E3 -> 46.724 | E3: =+Hoja3!F3 -> 887.756
A4: =CONCATENATE(Hoja3!A4,Hoja3!B4) -> V7419740 | B4: =+Hoja3!C4 -> ALVARADO YULITH | C4: =+Hoja3!D4 -> 985.38 | D4: =+Hoja3!E4 -> 49.269 | E4: =+Hoja3!F4 -> 936.111
A5: =CONCATENATE(Hoja3!A5,Hoja3!B5) -> V7419740 | B5: =+Hoja3!C5 -> ALVARADO YULITH | C5: =+Hoja3!D5 -> 151.8 | D5: =+Hoja3!E5 -> 7.59 | E5: =+Hoja3!F5 -> 151.8
A6: =CONCATENATE(Hoja3!A6,Hoja3!B6) -> V12020535 | B6: =+Hoja3!C6 -> ALVAREZ JOSE | C6: =+Hoja3!D6 -> 309.5 | D6: =+Hoja3!E6 -> 15.475 | E6: =+Hoja3!F6 -> 294.025
A7: =CONCATENATE(Hoja3!A7,Hoja3!B7) -> V12020535 | B7: =+Hoja3!C7 -> ALVAREZ JOSE | C7: =+Hoja3!D7 -> 152.2 | D7: =+Hoja3!E7 -> 7.61 | E7: =+Hoja3!F7 -> 144.59
A8: =CONCATENATE(Hoja3!A8,Hoja3!B8) -> V12701301 | B8: =+Hoja3!C8 -> AMARO PABLO | C8: =+Hoja3!D8 -> 301.91 | D8: =+Hoja3!E8 -> 15.0955 | E8: =+Hoja3!F8 -> 286.8145
A9: =CONCATENATE(Hoja3!A9,Hoja3!B9) -> V7442445 | B9: =+Hoja3!C9 -> CASTAÑEDA FRANCISCO | C9: =+Hoja3!D9 -> 173.89 | D9: =+Hoja3!E9 -> 8.6945 | E9: =+Hoja3!F9 -> 165.1955
A10: =CONCATENATE(Hoja3!A10,Hoja3!B10) -> V7442445 | B10: =+Hoja3!C10 -> CASTAÑEDA FRANCISCO | C10: =+Hoja3!D10 -> 220.01 | D10: =+Hoja3!E10 -> 11.0005 | E10: =+Hoja3!F10 -> 209.0095
A11: =CONCATENATE(Hoja3!A11,Hoja3!B11) -> V7442445 | B11: =+Hoja3!C11 -> CASTAÑEDA FRANCISCO | C11: =+Hoja3!D11 -> 30.32 | D11: =+Hoja3!E11 -> 1.516 | E11: =+Hoja3!F11 -> 30.32
A12: =CONCATENATE(Hoja3!A12,Hoja3!B12) -> V12314254 | B12: =+Hoja3!C12 -> CASTELLANOS VICENTE | C12: =+Hoja3!D12 -> 303.2 | D12: =+Hoja3!E12 -> 15.16 | E12: =+Hoja3!F12 -> 288.04
... A79: =CONCATENATE(Hoja3!A79,Hoja3!B79) -> V9613403 | B79: =+Hoja3!C79 -> RODRIGUEZ AIDA | C79: =+Hoja3!D79 -> 388.06 | D79: =+Hoja3!E79 -> 19.403 | E79: =+Hoja3!F79 -> 368.657
