Workbook

Sheet Hoja1
A3: FARMACIA UNIVERSIDAD
A4: C A P P O - U C L A
A5: Carrera 21 entre Calles 12 y 13 Nro 12-13 telef. 0251-2524973/2527081
A6: Relación de Cobranza
A7: CAPPO - UCLA
A8: Desde 12/11/12 Hasta: 24/11/12
A9: Fecha | B9: Apellido y Nombre | C9: Cédula | D9: Cod. Socio | E9: Factura | F9: Monto | G9: Dcto. Clte. | H9: Total Facturas | J9: Dcto. Cap. | K9: IVA | L9: Neto
A10: 41225 | B10: ALVARADO RAFAEL | C10: 10126656 | D10: 00180 | E10: 519914 | F10: 480.35 | G10: 96.07 | H10: 384.28 | J10: =H10*5% -> 19.214 | K10: 0 | L10: 365.066
A11: 41225 | B11: AMARO ANA | C11: 7374616 | D11: 00112 | E11: 519854 | F11: 592 | G11: 118.4 | H11: 473.6 | I11: 638.4 | J11: 23.68 | K11: 0 | L11: 449.92
A12: 41225 | B12: AMARO ANA | C12: 7374616 | D12: 00112 | E12: 519855 | F12: 206 | G12: 41.2 | H12: 164.8 | J12: 8.24 | K12: 0 | L12: 156.56
A13: 41225 | B13: APOSTOL R. CARLOS | C13: 10849906 | D13: 00151 | E13: 520280 | F13: 466.43 | G13: 70.49 | H13: 395.94 | J13: 19.797 | K13: 0 | L13: 376.143
A14: 41225 | B14: ARRIECHE IVONNE | C14: 9553047 | D14: 00164 | E14: 520080 | F14: 332.3 | G14: 63.17 | H14: 276.91 | I14: 1170.91 | J14: 13.8455 | K14: 7.78 | L14: 263.0645
A15: 41225 | B15: ARRIECHE IVONNE | C15: 9553047 | D15: 00164 | E15: 520081 | F15: 159 | G15: 31.8 | H15: 127.2 | J15: 6.36 | K15: 0 | L15: 120.84
A16: 41225 | B16: ARRIECHE IVONNE | C16: 9553047 | D16: 00164 | E16: 520354 | F16: 412.18 | G16: 78.4 | H16: 333.78 | J16: 16.689 | K16: 0 | L16: 317.091
A17: 41225 | B17: ARRIECHE IVONNE | C17: 9553047 | D17: 00164 | E17: 520355 | F17: 536.02 | G17: 103 | H17: 433.02 | J17: 21.651 | K17: 0 | L17: 411.369
A18: 41225 | B18: BELLO LAYA JULIO | C18: 7344290 | D18: 00222 | E18: 520402 | F18: 148.24 | G18: 22.4 | H18: 130.19 | J18: 6.5095 | K18: 4.35 | L18: 123.6805
A19: 41225 | B19: BULLONES PASTOR | C19: 3878006 | D19: 00219 | E19: 520139 | F19: 314.97 | G19: 42.99 | H19: 271.98 | I19: 480.01 | J19: 13.599 | K19: 0 | L19: 258.381
A20: 41225 | B20: BULLONES PASTOR | C20: 3878006 | D20: 00219 | E20: 520262 | F20: 199.33 | G20: 0 | H20: 208.03 | J20: 0 | K20: 8.7 | L20: 208.03
A21: 41225 | B21: CARMONA HORACIO | C21: 9620720 | D21: 00158 | E21: 519922 | F21: 671.71 | G21: 134.35 | H21: 537.36 | J21: 26.868 | K21: 0 | L21: 510.492
A22: 41225 | B22: CASTELLANOS VICENTE | C22: 12314254 | D22: 00304 | E22: 519930 | F22: 496 | G22: 99.2 | H22: 396.8 | J22: 19.84 | K22: 0 | L22: 376.96
A23: 41225 | B23: CASTILLO JOSE | C23: 10846532 | D23: 00361 | E23: 519846 | F23: 1490 | G23: 298 | H23: 1192 | J23: 59.6 | K23: 0 | L23: 1132.4
A24: 41225 | B24: COLMENAREZ JOSE | C24: 4375498 | D24: 00341 | E24: 519963 | F24: 228 | G24: 45.6 | H24: 182.4 | J24: 9.12 | K24: 0 | L24: 173.28
A25: 41225 | B25: COLMENAREZ CARLOS | C25: 7316059 | D25: 00364 | E25: 520344 | F25: 123.27 | G25: 22.88 | H25: 100.39 | J25: 5.0195 | K25: 0 | L25: 95.3705
A26: 41225 | B26: CORRALES CLARISA | C26: 9609337 | D26: 00343 | E26: 519939 | F26: 861 | G26: 172.2 | H26: 688.8 | J26: 34.44 | K26: 0 | L26: 654.36
A27: 41225 | B27: DAVILA CHACON INGRID | C27: 9211039 | D27: 00522 | E27: 520049 | F27: 150 | G27: 30 | H27: 120 | J27: 6 | K27: 0 | L27: 114
A28: 41226 | B28: DUARTE GENRY | C28: 10846474 | D28: 00519 | E28: 519874 | F28: 379.66 | G28: 72.04 | H28: 307.62 | I28: 353.76 | J28: 15.381 | K28: 0 | L28: 292.239
A29: 41226 | B29: DUARTE GENRY | C29: 10846474 | D29: 00519 | E29: 519875 | F29: 56.14 | G29: 10 | H29: 46.14 | J29: 2.307 | K29: 0 | L29: 43.833
A30: 41226 | B30: DURAN ADRIAN | C30: 4727740 | D30: 00500 | E30: 520002 | F30: 66.5 | G30: 13.3 | H30: 53.2 | J30: 2.66 | K30: 0 | L30: 50.54
A31: 41226 | B31: ESCALONA DIONICIO | C31: 9620701 | D31: 00624 | E31: 519829 | F31: 648 | G31: 129.6 | H31: 518.4 | I31: 670.15 | J31: 25.92 | K31: 0 | L31: 492.48
A32: 41226 | B32: ESCALONA DIONICIO | C32: 9620701 | D32: 00624 | E32: 519830 | F32: 174.35 | G32: 22.6 | H32: 151.75 | J32: 7.5875 | K32: 0 | L32: 144.1625
A33: 41227 | B33: GARCIA RUBEN | C33: 13527636 | D33: 00727 | E33: 520159 | F33: 592 | G33: 118.4 | H33: 473.6 | I33: 523.6 | J33: 23.68 | K33: 0 | L33: 449.92
A34: 41227 | B34: GARCIA RUBEN | C34: 13527636 | D34: 00727 | E34: 520160 | F34: 50 | G34: 0 | H34: 50 | J34: 0 | K34: 0 | L34: 50
A35: 41227 | B35: GOMEZ MEDINA JUAN | C35: 12704927 | D35: 00918 | E35: 520236 | F35: 50 | G35: 0 | H35: 50 | J35: 0 | K35: 0 | L35: 50
A36: 41227 | B36: GOMEZ MIRNA | C36: 9552709 | D36: 00820 | E36: 519872 | F36: 647.13 | G36: 114 | H36: 533.13 | J36: 26.6565 | K36: 0 | L36: 506.4735
A37: 41227 | B37: GONZALEZ GERARDO | C37: 7447067 | D37: 00936 | E37: 520045 | F37: 358.19 | G37: 69.71 | H37: 288.48 | I37: 1256.97 | J37: 14.424 | K37: 0 | L37: 274.056
A38: 41227 | B38: GONZALEZ GERARDO | C38: 7447067 | D38: 00936 | E38: 520046 | F38: 380.29 | G38: 75 | H38: 305.29 | J38: 15.2645 | K38: 0 | L38: 290.0255
A39: 41227 | B39: GONZALEZ GERARDO | C39: 7447067 | D39: 00936 | E39: 520173 | F39: 829 | G39: 165.8 | H39: 663.2 | J39: 33.16 | K39: 0 | L39: 630.04
A40: 41227 | B40: GRATEROL YAILILI | C40: 9615964 | D40: 00887 | E40: 520303 | F40: 475.71 | G40: 90 | H40: 385.71 | I40: 425.93 | J40: 19.2855 | K40: 0 | L40: 366.4245
A41: 41228 | B41: GRATEROL YAILILI | C41: 9615964 | D41: 00887 | E41: 520304 | F41: 50.28 | G41: 10.06 | H41: 40.22 | J41: 2.011 | K41: 0 | L41: 38.209
A42: 41228 | B42: GUASIMUCARO HENRY | C42: 7426046 | D42: 00889 | E42: 520154 | F42: 1116.09 | G42: 223.22 | H42: 892.87 | I42: 968.87 | J42: 44.6435 | K42: 0 | L42: 848.2265
...

Sheet Hoja2
A1: V | B1: =+Hoja1!C10 -> 10126656 | C1: =+Hoja1!B10 -> ALVARADO RAFAEL | D1: =+Hoja1!H10 -> 384.28 | E1: =+Hoja1!J10 -> 19.214 | F1: =+Hoja1!L10 -> 365.066
A2: V | B2: =+Hoja1!C11 -> 7374616 | C2: =+Hoja1!B11 -> AMARO ANA | D2: =+Hoja1!H11 -> 473.6 | E2: =+Hoja1!J11 -> 23.68 | F2: =+Hoja1!L11 -> 449.92
A3: V | B3: =+Hoja1!C12 -> 7374616 | C3: =+Hoja1!B12 -> AMARO ANA | D3: =+Hoja1!H12 -> 164.8 | E3: =+Hoja1!J12 -> 8.24 | F3: =+Hoja1!L12 -> 156.56
A4: V | B4: =+Hoja1!C13 -> 10849906 | C4: =+Hoja1!B13 -> APOSTOL R. CARLOS | D4: =+Hoja1!H13 -> 395.94 | E4: =+Hoja1!J13 -> 19.797 | F4: =+Hoja1!L13 -> 376.143
A5: V | B5: =+Hoja1!C14 -> 9553047 | C5: =+Hoja1!B14 -> ARRIECHE IVONNE | D5: =+Hoja1!H14 -> 276.91 | E5: =+Hoja1!J14 -> 13.8455 | F5: =+Hoja1!L14 -> 263.0645
A6: V | B6: =+Hoja1!C15 -> 9553047 | C6: =+Hoja1!B15 -> ARRIECHE IVONNE | D6: =+Hoja1!H15 -> 127.2 | E6: =+Hoja1!J15 -> 6.36 | F6: =+Hoja1!L15 -> 120.84
A7: V | B7: =+Hoja1!C16 -> 9553047 | C7: =+Hoja1!B16 -> ARRIECHE IVONNE | D7: =+Hoja1!H16 -> 333.78 | E7: =+Hoja1!J16 -> 16.689 | F7: =+Hoja1!L16 -> 317.091
A8: V | B8: =+Hoja1!C17 -> 9553047 | C8: =+Hoja1!B17 -> ARRIECHE IVONNE | D8: =+Hoja1!H17 -> 433.02 | E8: =+Hoja1!J17 -> 21.651 | F8: =+Hoja1!L17 -> 411.369
A9: V | B9: =+Hoja1!C18 -> 7344290 | C9: =+Hoja1!B18 -> BELLO LAYA JULIO | D9: =+Hoja1!H18 -> 130.19 | E9: =+Hoja1!J18 -> 6.5095 | F9: =+Hoja1!L18 -> 123.6805
A10: V | B10: =+Hoja1!C19 -> 3878006 | C10: =+Hoja1!B19 -> BULLONES PASTOR | D10: =+Hoja1!H19 -> 271.98 | E10: =+Hoja1!J19 -> 13.599 | F10: =+Hoja1!L19 -> 258.381
A11: V | B11: =+Hoja1!C20 -> 3878006 | C11: =+Hoja1!B20 -> BULLONES PASTOR | D11: =+Hoja1!H20 -> 208.03 | E11: =+Hoja1!J20 -> 0 | F11: =+Hoja1!L20 -> 208.03
A12: V | B12: =+Hoja1!C21 -> 9620720 | C12: =+Hoja1!B21 -> CARMONA HORACIO | D12: =+Hoja1!H21 -> 537.36 | E12: =+Hoja1!J21 -> 26.868 | F12: =+Hoja1!L21 -> 510.492
... A86: V | B86: =+Hoja1!C95 -> 5436619 | C86: =+Hoja1!B95 -> YUSTIZ JOSE | D86: =+Hoja1!H95 -> 1584 | E86: =+Hoja1!J95 -> 79.2 | F86: =+Hoja1!L95 -> 1504.8

Sheet Hoja3
A1: =CONCATENATE(Hoja2!A1,Hoja2!B1) -> V10126656 | B1: =+Hoja2!C1 -> ALVARADO RAFAEL | C1: =+Hoja2!D1 -> 384.28 | D1: =+Hoja2!E1 -> 19.214 | E1: =+Hoja2!F1 -> 365.066
A2: =CONCATENATE(Hoja2!A2,Hoja2!B2) -> V7374616 | B2: =+Hoja2!C2 -> AMARO ANA | C2: =+Hoja2!D2 -> 473.6 | D2: =+Hoja2!E2 -> 23.68 | E2: =+Hoja2!F2 -> 449.92
A3: =CONCATENATE(Hoja2!A3,Hoja2!B3) -> V7374616 | B3: =+Hoja2!C3 -> AMARO ANA | C3: =+Hoja2!D3 -> 164.8 | D3: =+Hoja2!E3 -> 8.24 | E3: =+Hoja2!F3 -> 156.56
A4: =CONCATENATE(Hoja2!A4,Hoja2!B4) -> V10849906 | B4: =+Hoja2!C4 -> APOSTOL R. CARLOS | C4: =+Hoja2!D4 -> 395.94 | D4: =+Hoja2!E4 -> 19.797 | E4: =+Hoja2!F4 -> 376.143
A5: =CONCATENATE(Hoja2!A5,Hoja2!B5) -> V9553047 | B5: =+Hoja2!C5 -> ARRIECHE IVONNE | C5: =+Hoja2!D5 -> 276.91 | D5: =+Hoja2!E5 -> 13.8455 | E5: =+Hoja2!F5 -> 263.0645
A6: =CONCATENATE(Hoja2!A6,Hoja2!B6) -> V9553047 | B6: =+Hoja2!C6 -> ARRIECHE IVONNE | C6: =+Hoja2!D6 -> 127.2 | D6: =+Hoja2!E6 -> 6.36 | E6: =+Hoja2!F6 -> 120.84
A7: =CONCATENATE(Hoja2!A7,Hoja2!B7) -> V9553047 | B7: =+Hoja2!C7 -> ARRIECHE IVONNE | C7: =+Hoja2!D7 -> 333.78 | D7: =+Hoja2!E7 -> 16.689 | E7: =+Hoja2!F7 -> 317.091
A8: =CONCATENATE(Hoja2!A8,Hoja2!B8) -> V9553047 | B8: =+Hoja2!C8 -> ARRIECHE IVONNE | C8: =+Hoja2!D8 -> 433.02 | D8: =+Hoja2!E8 -> 21.651 | E8: =+Hoja2!F8 -> 411.369
A9: =CONCATENATE(Hoja2!A9,Hoja2!B9) -> V7344290 | B9: =+Hoja2!C9 -> BELLO LAYA JULIO | C9: =+Hoja2!D9 -> 130.19 | D9: =+Hoja2!E9 -> 6.5095 | E9: =+Hoja2!F9 -> 123.6805
A10: =CONCATENATE(Hoja2!A10,Hoja2!B10) -> V3878006 | B10: =+Hoja2!C10 -> BULLONES PASTOR | C10: =+Hoja2!D10 -> 271.98 | D10: =+Hoja2!E10 -> 13.599 | E10: =+Hoja2!F10 -> 258.381
A11: =CONCATENATE(Hoja2!A11,Hoja2!B11) -> V3878006 | B11: =+Hoja2!C11 -> BULLONES PASTOR | C11: =+Hoja2!D11 -> 208.03 | D11: =+Hoja2!E11 -> 0 | E11: =+Hoja2!F11 -> 208.03
A12: =CONCATENATE(Hoja2!A12,Hoja2!B12) -> V9620720 | B12: =+Hoja2!C12 -> CARMONA HORACIO | C12: =+Hoja2!D12 -> 537.36 | D12: =+Hoja2!E12 -> 26.868 | E12: =+Hoja2!F12 -> 510.492
... A86: =CONCATENATE(Hoja2!A86,Hoja2!B86) -> V5436619 | B86: =+Hoja2!C86 -> YUSTIZ JOSE | C86: =+Hoja2!D86 -> 1584 | D86: =+Hoja2!E86 -> 79.2 | E86: =+Hoja2!F86 -> 1504.8
